Workbook

Sheet Data
B2: New Subscription Calls
B4: Date | C4: New Calls
B5: 45047 | C5: 1576
B6: 45048 | C6: 2299
B7: 45049 | C7: 1878
B8: 45050 | C8: 1628
B9: 45051 | C9: 1555
B10: 45052 | C10: 1240
B11: 45053 | C11: 864
B12: 45054 | C12: 1882
B13: 45055 | C13: 2306
B14: 45056 | C14: 1988
B15: 45057 | C15: 1886
B16: 45058 | C16: 1365
... B60: 45102 | C60: 1615

Sheet 2.1 CMA
B2: Date | C2: New Calls | D2: CMA-3 | E2: CMA-7 | F2: CMA-14
B3: 45047 | C3: 1576
B4: 45048 | C4: 2299 | D4: =AVERAGE(C3:C5) -> 1917.6667
B5: 45049 | C5: 1878 | D5: =AVERAGE(C4:C6) -> 1935
B6: 45050 | C6: 1628 | D6: =AVERAGE(C5:C7) -> 1687 | E6: =AVERAGE(C3:C9) -> 1577.1429
B7: 45051 | C7: 1555 | D7: =AVERAGE(C6:C8) -> 1474.3333 | E7: =AVERAGE(C4:C10) -> 1620.8571
B8: 45052 | C8: 1240 | D8: =AVERAGE(C7:C9) -> 1219.6667 | E8: =AVERAGE(C5:C11) -> 1621.8571
B9: 45053 | C9: 864 | D9: =AVERAGE(C8:C10) -> 1328.6667 | E9: =AVERAGE(C6:C12) -> 1637.5714
B10: 45054 | C10: 1882 | D10: =AVERAGE(C9:C11) -> 1684 | E10: =AVERAGE(C7:C13) -> 1674.4286 | F10: =(C3/2+SUM(C4:C16)+C17/2)/14 -> 1620.1071
B11: 45055 | C11: 2306 | D11: =AVERAGE(C10:C12) -> 2058.6667 | E11: =AVERAGE(C8:C14) -> 1647.2857 | F11: =(C4/2+SUM(C5:C17)+C18/2)/14 -> 1612.8571
B12: 45056 | C12: 1988 | D12: =AVERAGE(C11:C13) -> 2060 | E12: =AVERAGE(C9:C15) -> 1612.7143 | F12: =(C5/2+SUM(C6:C18)+C19/2)/14 -> 1595.0357
B13: 45057 | C13: 1886 | D13: =AVERAGE(C12:C14) -> 1746.3333 | E13: =AVERAGE(C10:C16) -> 1639.5714 | F13: =(C6/2+SUM(C7:C19)+C20/2)/14 -> 1610.7857
B14: 45058 | C14: 1365 | D14: =AVERAGE(C13:C15) -> 1416.3333 | E14: =AVERAGE(C11:C17) -> 1642.8571 | F14: =(C7/2+SUM(C8:C20)+C21/2)/14 -> 1620.8214
B15: 45059 | C15: 998 | D15: =AVERAGE(C14:C16) -> 1138.3333 | E15: =AVERAGE(C12:C18) -> 1565.8571 | F15: =(C8/2+SUM(C9:C21)+C22/2)/14 -> 1608
B16: 45060 | C16: 1052 | D16: =AVERAGE(C15:C17) -> 1318.3333 | E16: =AVERAGE(C13:C19) -> 1554.8571 | F16: =(C9/2+SUM(C10:C22)+C23/2)/14 -> 1607.5
B17: 45061 | C17: 1905 | D17: =AVERAGE(C16:C18) -> 1574.6667 | E17: =AVERAGE(C14:C20) -> 1576.2857 | F17: =(C10/2+SUM(C11:C23)+C24/2)/14 -> 1616.6786
B18: 45062 | C18: 1767 | D18: =AVERAGE(C17:C19) -> 1861 | E18: =AVERAGE(C15:C21) -> 1585.2857 | F18: =(C11/2+SUM(C12:C24)+C25/2)/14 -> 1599.2857
B19: 45063 | C19: 1911 | D19: =AVERAGE(C18:C20) -> 1904.6667 | E19: =AVERAGE(C16:C22) -> 1586.7143 | F19: =(C12/2+SUM(C13:C25)+C26/2)/14 -> 1583.4643
B20: 45064 | C20: 2036 | D20: =AVERAGE(C19:C21) -> 1791.6667 | E20: =AVERAGE(C17:C23) -> 1591 | F20: =(C13/2+SUM(C14:C26)+C27/2)/14 -> 1583.8214
B21: 45065 | C21: 1428 | D21: =AVERAGE(C20:C22) -> 1490.6667 | E21: =AVERAGE(C18:C24) -> 1593.2857 | F21: =(C14/2+SUM(C15:C27)+C28/2)/14 -> 1596.0357
... B58: 45102 | C58: 1615 | D58: =AVERAGE(C57:C59) -> 1608 | E58: =AVERAGE(C55:C61) -> 2126 | F58: =(C51/2+SUM(C52:C64)+C65/2)/14 -> 1271.0714

Sheet 2.2 Removing Trend
B3: Date | C3: New Calls | D3: CMA-7 | E3: Detrended Time Series
B4: 45047 | C4: 1576
B5: 45048 | C5: 2299
B6: 45049 | C6: 1878
B7: 45050 | C7: 1628 | D7: =AVERAGE(C4:C10) -> 1577.1429 | E7: =C7-D7 -> 50.857143
B8: 45051 | C8: 1555 | D8: =AVERAGE(C5:C11) -> 1620.8571 | E8: =C8-D8 -> -65.857143
B9: 45052 | C9: 1240 | D9: =AVERAGE(C6:C12) -> 1621.8571 | E9: =C9-D9 -> -381.85714
B10: 45053 | C10: 864 | D10: =AVERAGE(C7:C13) -> 1637.5714 | E10: =C10-D10 -> -773.57143
B11: 45054 | C11: 1882 | D11: =AVERAGE(C8:C14) -> 1674.4286 | E11: =C11-D11 -> 207.57143
B12: 45055 | C12: 2306 | D12: =AVERAGE(C9:C15) -> 1647.2857 | E12: =C12-D12 -> 658.71429
B13: 45056 | C13: 1988 | D13: =AVERAGE(C10:C16) -> 1612.7143 | E13: =C13-D13 -> 375.28571
B14: 45057 | C14: 1886 | D14: =AVERAGE(C11:C17) -> 1639.5714 | E14: =C14-D14 -> 246.42857
B15: 45058 | C15: 1365 | D15: =AVERAGE(C12:C18) -> 1642.8571 | E15: =C15-D15 -> -277.85714
B16: 45059 | C16: 998 | D16: =AVERAGE(C13:C19) -> 1565.8571 | E16: =C16-D16 -> -567.85714
B17: 45060 | C17: 1052 | D17: =AVERAGE(C14:C20) -> 1554.8571 | E17: =C17-D17 -> -502.85714
B18: 45061 | C18: 1905 | D18: =AVERAGE(C15:C21) -> 1576.2857 | E18: =C18-D18 -> 328.71429
... B56: 45099 | C56: 2338 | D56: =AVERAGE(C53:C59) -> 2441.5714 | E56: =C56-D56 -> -103.57143
B57: 45100 | C57: 2950
B58: 45101 | C58: 1601
B59: 45102 | C59: 1615

Sheet 2.3 Identify Seasonality
B2: Date | C2: New Calls | D2: CMA7 | E2: Detrended Time series | F2: Week | G2: Day
B3: 45047 | C3: 1576
B4: 45048 | C4: 2299
B5: 45049 | C5: 1878 | J5: Day/Week | K5: Week-1 | L5: Week-2 | M5: Week-3 | N5: Week-4 | O5: Week-5 | P5: Week-6 | Q5: Week-7 | R5: Week-8
B6: 45050 | C6: 1628 | D6: {='2.2 Removing Trend'!D7:E56} -> 1577.1429 | E6: 50.857143 | F6: 1 | G6: =TEXT(B6,"ddd") -> Thu | J6: 45061 | L6: =E10 -> 207.57143 | M6: =E17 -> 328.71429 | N6: =E24 -> 334.85714 | O6: =E31 -> 162 | P6: =E38 -> 754.85714 | Q6: =E45 -> 630.42857 | R6: =E52 -> 590.42857
B7: 45051 | C7: 1555 | D7: 1620.8571 | E7: -65.857143 | F7: 1 | G7: =TEXT(B7,"ddd") -> Fri | J7: 45062 | L7: =E11 -> 658.71429 | M7: =E18 -> 181.71429 | N7: =E25 -> 143.57143 | O7: =E32 -> 180.71429 | P7: =E39 -> 530.71429 | Q7: =E46 -> -49.285714 | R7: =E53 -> 209.42857
B8: 45052 | C8: 1240 | D8: 1621.8571 | E8: -381.85714 | F8: 1 | G8: =TEXT(B8,"ddd") -> Sat | J8: 45063 | L8: =E12 -> 375.28571 | M8: =E19 -> 324.28571 | N8: =E26 -> 402 | O8: =E33 -> 339.85714 | P8: =E40 -> 720.14286 | Q8: =E47 -> 440.42857 | R8: =E54 -> 608
B9: 45053 | C9: 864 | D9: 1637.5714 | E9: -773.57143 | F9: 1 | G9: =TEXT(B9,"ddd") -> Sun | J9: 45064 | K9: =E6 -> 50.857143 | L9: =E13 -> 246.42857 | M9: =E20 -> 445 | N9: =E27 -> 144 | O9: =E34 -> 235.42857 | P9: =E41 -> 281.85714 | Q9: =E48 -> 780.57143 | R9: =E55 -> -103.57143
B10: 45054 | C10: 1882 | D10: 1674.4286 | E10: 207.57143 | F10: 2 | G10: =TEXT(B10,"ddd") -> Mon | J10: 45065 | K10: =E7 -> -65.857143 | L10: =E14 -> -277.85714 | M10: =E21 -> -165.28571 | N10: =E28 -> 131.57143 | O10: =E35 -> -135.42857 | P10: =E42 -> -152.57143 | Q10: =E49 -> -212.42857
B11: 45055 | C11: 2306 | D11: 1647.2857 | E11: 658.71429 | F11: 2 | G11: =TEXT(B11,"ddd") -> Tue | J11: 45066 | K11: =E8 -> -381.85714 | L11: =E15 -> -567.85714 | M11: =E22 -> -587.14286 | N11: =E29 -> -410.42857 | O11: =E36 -> -907.28571 | P11: =E43 -> -884.71429 | Q11: =E50 -> -661.28571
B12: 45056 | C12: 1988 | D12: 1612.7143 | E12: 375.28571 | F12: 2 | G12: =TEXT(B12,"ddd") -> Wed | J12: 45067 | K12: =E9 -> -773.57143 | L12: =E16 -> -502.85714 | M12: =E23 -> -536 | N12: =E30 -> -537.71429 | O12: =E37 -> -940.42857 | P12: =E44 -> -616.57143 | Q12: =E51 -> -1046.5714
B13: 45057 | C13: 1886 | D13: 1639.5714 | E13: 246.42857 | F13: 2 | G13: =TEXT(B13,"ddd") -> Thu
B14: 45058 | C14: 1365 | D14: 1642.8571 | E14: -277.85714 | F14: 2 | G14: =TEXT(B14,"ddd") -> Fri
B15: 45059 | C15: 998 | D15: 1565.8571 | E15: -567.85714 | F15: 2 | G15: =TEXT(B15,"ddd") -> Sat
B16: 45060 | C16: 1052 | D16: 1554.8571 | E16: -502.85714 | F16: 2 | G16: =TEXT(B16,"ddd") -> Sun
B17: 45061 | C17: 1905 | D17: 1576.2857 | E17: 328.71429 | F17: 3 | G17: =TEXT(B17,"ddd") -> Mon
B18: 45062 | C18: 1767 | D18: 1585.2857 | E18: 181.71429 | F18: 3 | G18: =TEXT(B18,"ddd") -> Tue
B19: 45063 | C19: 1911 | D19: 1586.7143 | E19: 324.28571 | F19: 3 | G19: =TEXT(B19,"ddd") -> Wed
B20: 45064 | C20: 2036 | D20: 1591 | E20: 445 | F20: 3 | G20: =TEXT(B20,"ddd") -> Thu
B21: 45065 | C21: 1428 | D21: 1593.2857 | E21: -165.28571 | F21: 3 | G21: =TEXT(B21,"ddd") -> Fri
B22: 45066 | C22: 1008 | D22: 1595.1429 | E22: -587.14286 | F22: 3 | G22: =TEXT(B22,"ddd") -> Sat
B23: 45067 | C23: 1082 | D23: 1618 | E23: -536 | F23: 3 | G23: =TEXT(B23,"ddd") -> Sun
B24: 45068 | C24: 1921 | D24: 1586.1429 | E24: 334.85714 | F24: 4 | G24: =TEXT(B24,"ddd") -> Mon
... B55: 45099 | C55: 2338 | D55: 2441.5714 | E55: -103.57143 | F55: 8 | G55: =TEXT(B55,"ddd") -> Thu
B56: 45100 | C56: 2950 | G56: =TEXT(B56,"ddd") -> Fri
B57: 45101 | C57: 1601 | G57: =TEXT(B57,"ddd") -> Sat
B58: 45102 | C58: 1615 | G58: =TEXT(B58,"ddd") -> Sun

Sheet 2.4 Estimated Seasonal Pattern
C4: Day/Week | D4: Week-1 | E4: Week-2 | F4: Week-3 | G4: Week-4 | H4: Week-5 | I4: Week-6 | J4: Week-7 | K4: Week-8 | N4: Day | O4: Median Seasonal Profile | Q4: Day | R4: Median Seasonal Profile | S4: Adjusted Seasonal Profile
C5: 45061 | E5: {='2.3 Identify Seasonality'!L6:Q12} -> 207.57143 | F5: 328.71429 | G5: 334.85714 | H5: 162 | I5: 754.85714 | J5: 630.42857 | K5: {='2.3 Identify Seasonality'!R6:R10} -> 590.42857 | N5: 45061 | O5: =AVERAGE(E5:K5) -> 429.83673 | Q5: 45061 | R5: =O5 -> 429.83673 | S5: =R5-$R$13 -> 436.71866
C6: 45062 | E6: 658.71429 | F6: 181.71429 | G6: 143.57143 | H6: 180.71429 | I6: 530.71429 | J6: -49.285714 | K6: 209.42857 | N6: 45062 | O6: =AVERAGE(E6:K6) -> 265.08163 | Q6: 45062 | R6: =O6 -> 265.08163 | S6: =R6-$R$13 -> 271.96356
C7: 45063 | E7: 375.28571 | F7: 324.28571 | G7: 402 | H7: 339.85714 | I7: 720.14286 | J7: 440.42857 | K7: 608 | N7: 45063 | O7: =AVERAGE(E7:K7) -> 458.57143 | Q7: 45063 | R7: =O7 -> 458.57143 | S7: =R7-$R$13 -> 465.45335
C8: 45064 | D8: {='2.3 Identify Seasonality'!K9:K12} -> 50.857143 | E8: 246.42857 | F8: 445 | G8: 144 | H8: 235.42857 | I8: 281.85714 | J8: 780.57143 | K8: -103.57143 | N8: 45064 | O8: =AVERAGE(D8:K8) -> 260.07143 | Q8: 45064 | R8: =O8 -> 260.07143 | S8: =R8-$R$13 -> 266.95335
C9: 45065 | D9: -65.857143 | E9: -277.85714 | F9: -165.28571 | G9: 131.57143 | H9: -135.42857 | I9: -152.57143 | J9: -212.42857 | K9: 0 | N9: 45065 | O9: =AVERAGE(D9:J9) -> -125.40816 | Q9: 45065 | R9: =O9 -> -125.40816 | S9: =R9-$R$13 -> -118.52624
C10: 45066 | D10: -381.85714 | E10: -567.85714 | F10: -587.14286 | G10: -410.42857 | H10: -907.28571 | I10: -884.71429 | J10: -661.28571 | N10: 45066 | O10: =AVERAGE(D10:J10) -> -628.65306 | Q10: 45066 | R10: =O10 -> -628.65306 | S10: =R10-$R$13 -> -621.77114
C11: 45067 | D11: -773.57143 | E11: -502.85714 | F11: -536 | G11: -537.71429 | H11: -940.42857 | I11: -616.57143 | J11: -1046.5714 | N11: 45067 | O11: =AVERAGE(D11:J11) -> -707.67347 | Q11: 45067 | R11: =O11 -> -707.67347 | S11: =R11-$R$13 -> -700.79155
R12: =SUM(R5:R11) -> -48.173469 | S12: =SUM(S5:S12) -> 0
R13: =R12/7 -> -6.8819242

Sheet 2.5 Noise
B3: Date | C3: New Calls | D3: CMA-7 | E3: Average Seasonal Indices | F3: Season and Trend | G3: Noise
B4: 45047 | C4: 1576
B5: 45048 | C5: 2299
B6: 45049 | C6: 1878
B7: 45050 | C7: 1628 | D7: ='2.3 Identify Seasonality'!D6 -> 1577.1429 | E7: ='2.4 Estimated Seasonal Pattern'!O8 -> 260.07143 | F7: =D7+E7 -> 1837.2143 | G7: =C7-F7 -> -209.21429
B8: 45051 | C8: 1555 | D8: ='2.3 Identify Seasonality'!D7 -> 1620.8571 | E8: ='2.4 Estimated Seasonal Pattern'!O9 -> -125.40816 | F8: =D8+E8 -> 1495.449 | G8: =C8-F8 -> 59.55102
B9: 45052 | C9: 1240 | D9: ='2.3 Identify Seasonality'!D8 -> 1621.8571 | E9: ='2.4 Estimated Seasonal Pattern'!O10 -> -628.65306 | F9: =D9+E9 -> 993.20408 | G9: =C9-F9 -> 246.79592
B10: 45053 | C10: 864 | D10: ='2.3 Identify Seasonality'!D9 -> 1637.5714 | E10: ='2.4 Estimated Seasonal Pattern'!O11 -> -707.67347 | F10: =D10+E10 -> 929.89796 | G10: =C10-F10 -> -65.897959
B11: 45054 | C11: 1882 | D11: ='2.3 Identify Seasonality'!D10 -> 1674.4286 | E11: ='2.4 Estimated Seasonal Pattern'!R5 -> 429.83673 | F11: =D11+E11 -> 2104.2653 | G11: =C11-F11 -> -222.26531
B12: 45055 | C12: 2306 | D12: ='2.3 Identify Seasonality'!D11 -> 1647.2857 | E12: ='2.4 Estimated Seasonal Pattern'!R6 -> 265.08163 | F12: =D12+E12 -> 1912.3673 | G12: =C12-F12 -> 393.63265
B13: 45056 | C13: 1988 | D13: ='2.3 Identify Seasonality'!D12 -> 1612.7143 | E13: ='2.4 Estimated Seasonal Pattern'!R7 -> 458.57143 | F13: =D13+E13 -> 2071.2857 | G13: =C13-F13 -> -83.285714
B14: 45057 | C14: 1886 | D14: ='2.3 Identify Seasonality'!D13 -> 1639.5714 | E14: ='2.4 Estimated Seasonal Pattern'!R8 -> 260.07143 | F14: =D14+E14 -> 1899.6429 | G14: =C14-F14 -> -13.642857
B15: 45058 | C15: 1365 | D15: ='2.3 Identify Seasonality'!D14 -> 1642.8571 | E15: ='2.4 Estimated Seasonal Pattern'!R9 -> -125.40816 | F15: =D15+E15 -> 1517.449 | G15: =C15-F15 -> -152.44898
B16: 45059 | C16: 998 | D16: ='2.3 Identify Seasonality'!D15 -> 1565.8571 | E16: ='2.4 Estimated Seasonal Pattern'!R10 -> -628.65306 | F16: =D16+E16 -> 937.20408 | G16: =C16-F16 -> 60.795918
B17: 45060 | C17: 1052 | D17: ='2.3 Identify Seasonality'!D16 -> 1554.8571 | E17: ='2.4 Estimated Seasonal Pattern'!R11 -> -707.67347 | F17: =D17+E17 -> 847.18367 | G17: =C17-F17 -> 204.81633
B18: 45061 | C18: 1905 | D18: ='2.3 Identify Seasonality'!D17 -> 1576.2857 | E18: ='2.4 Estimated Seasonal Pattern'!O5 -> 429.83673 | F18: =D18+E18 -> 2006.1224 | G18: =C18-F18 -> -101.12245
B19: 45062 | C19: 1767 | D19: ='2.3 Identify Seasonality'!D18 -> 1585.2857 | E19: ='2.4 Estimated Seasonal Pattern'!O6 -> 265.08163 | F19: =D19+E19 -> 1850.3673 | G19: =C19-F19 -> -83.367347
B20: 45063 | C20: 1911 | D20: ='2.3 Identify Seasonality'!D19 -> 1586.7143 | E20: ='2.4 Estimated Seasonal Pattern'!O7 -> 458.57143 | F20: =D20+E20 -> 2045.2857 | G20: =C20-F20 -> -134.28571
B21: 45064 | C21: 2036 | D21: ='2.3 Identify Seasonality'!D20 -> 1591 | E21: ='2.4 Estimated Seasonal Pattern'!O8 -> 260.07143 | F21: =D21+E21 -> 1851.0714 | G21: =C21-F21 -> 184.92857
B22: 45065 | C22: 1428 | D22: ='2.3 Identify Seasonality'!D21 -> 1593.2857 | E22: ='2.4 Estimated Seasonal Pattern'!O9 -> -125.40816 | F22: =D22+E22 -> 1467.8776 | G22: =C22-F22 -> -39.877551
B23: 45066 | C23: 1008 | D23: ='2.3 Identify Seasonality'!D22 -> 1595.1429 | E23: ='2.4 Estimated Seasonal Pattern'!O10 -> -628.65306 | F23: =D23+E23 -> 966.4898 | G23: =C23-F23 -> 41.510204
B24: 45067 | C24: 1082 | D24: ='2.3 Identify Seasonality'!D23 -> 1618 | E24: ='2.4 Estimated Seasonal Pattern'!O11 -> -707.67347 | F24: =D24+E24 -> 910.32653 | G24: =C24-F24 -> 171.67347
B25: 45068 | C25: 1921 | D25: ='2.3 Identify Seasonality'!D24 -> 1586.1429 | E25: ='2.4 Estimated Seasonal Pattern'!O5 -> 429.83673 | F25: =D25+E25 -> 2015.9796 | G25: =C25-F25 -> -94.979592
B26: 45069 | C26: 1780 | D26: ='2.3 Identify Seasonality'!D25 -> 1636.4286 | E26: ='2.4 Estimated Seasonal Pattern'!O6 -> 265.08163 | F26: =D26+E26 -> 1901.5102 | G26: =C26-F26 -> -121.5102
B27: 45070 | C27: 2071 | D27: ='2.3 Identify Seasonality'!D26 -> 1669 | E27: ='2.4 Estimated Seasonal Pattern'!O7 -> 458.57143 | F27: =D27+E27 -> 2127.5714 | G27: =C27-F27 -> -56.571429
B28: 45071 | C28: 1813 | D28: ='2.3 Identify Seasonality'!D27 -> 1669 | E28: ='2.4 Estimated Seasonal Pattern'!O8 -> 260.07143 | F28: =D28+E28 -> 1929.0714 | G28: =C28-F28 -> -116.07143
B29: 45072 | C29: 1780 | D29: ='2.3 Identify Seasonality'!D28 -> 1648.4286 | E29: ='2.4 Estimated Seasonal Pattern'!O9 -> -125.40816 | F29: =D29+E29 -> 1523.0204 | G29: =C29-F29 -> 256.97959
B30: 45073 | C30: 1236 | D30: ='2.3 Identify Seasonality'!D29 -> 1646.4286 | E30: ='2.4 Estimated Seasonal Pattern'!O10 -> -628.65306 | F30: =D30+E30 -> 1017.7755 | G30: =C30-F30 -> 218.22449
B31: 45074 | C31: 1082 | D31: ='2.3 Identify Seasonality'!D30 -> 1619.7143 | E31: ='2.4 Estimated Seasonal Pattern'!O11 -> -707.67347 | F31: =D31+E31 -> 912.04082 | G31: =C31-F31 -> 169.95918
B32: 45075 | C32: 1777 | D32: ='2.3 Identify Seasonality'!D31 -> 1615 | E32: ='2.4 Estimated Seasonal Pattern'!O5 -> 429.83673 | F32: =D32+E32 -> 2044.8367 | G32: =C32-F32 -> -267.83673
B33: 45076 | C33: 1766 | D33: ='2.3 Identify Seasonality'!D32 -> 1585.2857 | E33: ='2.4 Estimated Seasonal Pattern'!O6 -> 265.08163 | F33: =D33+E33 -> 1850.3673 | G33: =C33-F33 -> -84.367347
B34: 45077 | C34: 1884 | D34: ='2.3 Identify Seasonality'!D33 -> 1544.1429 | E34: ='2.4 Estimated Seasonal Pattern'!O7 -> 458.57143 | F34: =D34+E34 -> 2002.7143 | G34: =C34-F34 -> -118.71429
B35: 45078 | C35: 1780 | D35: ='2.3 Identify Seasonality'!D34 -> 1544.5714 | E35: ='2.4 Estimated Seasonal Pattern'!O8 -> 260.07143 | F35: =D35+E35 -> 1804.6429 | G35: =C35-F35 -> -24.642857
B36: 45079 | C36: 1572 | D36: ='2.3 Identify Seasonality'!D35 -> 1707.4286 | E36: ='2.4 Estimated Seasonal Pattern'!O9 -> -125.40816 | F36: =D36+E36 -> 1582.0204 | G36: =C36-F36 -> -10.020408
B37: 45080 | C37: 948 | D37: ='2.3 Identify Seasonality'!D36 -> 1855.2857 | E37: ='2.4 Estimated Seasonal Pattern'!O10 -> -628.65306 | F37: =D37+E37 -> 1226.6327 | G37: =C37-F37 -> -278.63265
B38: 45081 | C38: 1085 | D38: ='2.3 Identify Seasonality'!D37 -> 2025.4286 | E38: ='2.4 Estimated Seasonal Pattern'!O11 -> -707.67347 | F38: =D38+E38 -> 1317.7551 | G38: =C38-F38 -> -232.7551
B39: 45082 | C39: 2917 | D39: ='2.3 Identify Seasonality'!D38 -> 2162.1429 | E39: ='2.4 Estimated Seasonal Pattern'!O5 -> 429.83673 | F39: =D39+E39 -> 2591.9796 | G39: =C39-F39 -> 325.02041
B40: 45083 | C40: 2801 | D40: ='2.3 Identify Seasonality'!D39 -> 2270.2857 | E40: ='2.4 Estimated Seasonal Pattern'!O6 -> 265.08163 | F40: =D40+E40 -> 2535.3673 | G40: =C40-F40 -> 265.63265
B41: 45084 | C41: 3075 | D41: ='2.3 Identify Seasonality'!D40 -> 2354.8571 | E41: ='2.4 Estimated Seasonal Pattern'!O7 -> 458.57143 | F41: =D41+E41 -> 2813.4286 | G41: =C41-F41 -> 261.57143
B42: 45085 | C42: 2737 | D42: ='2.3 Identify Seasonality'!D41 -> 2455.1429 | E42: ='2.4 Estimated Seasonal Pattern'!O8 -> 260.07143 | F42: =D42+E42 -> 2715.2143 | G42: =C42-F42 -> 21.785714
...

Sheet 3.1 Seasonal Naive
B2: Date | C2: New Calls | D2: Week | E2: Day | F2: Seasonal Naïve forecast | G2: Error | H2: Absolute Error | I2: Squared Error
B3: 45047 | C3: 1576
B4: 45048 | C4: 2299
B5: 45049 | C5: 1878 | L5: In-sample
B6: 45050 | C6: 1628 | D6: {='2.3 Identify Seasonality'!F6:G55} -> 1 | E6: Thu
B7: 45051 | C7: 1555 | D7: 1 | E7: Fri | L7: Mean Error | M7: =AVERAGE(G3:G51) -> 142.54762
B8: 45052 | C8: 1240 | D8: 1 | E8: Sat | L8: Mean Absoulute Error | M8: =AVERAGE(H10:H51) -> 295.16667
B9: 45053 | C9: 864 | D9: 1 | E9: Sun | L9: Mean Squared Error | M9: =AVERAGE(I10:I51) -> 186754.79
B10: 45054 | C10: 1882 | D10: 2 | E10: Mon | F10: 1576 | G10: =C10-F10 -> 306 | H10: =ABS(G10) -> 306 | I10: =G10^2 -> 93636 | L10: RMSE | M10: =SQRT($M$9) -> 432.15135
B11: 45055 | C11: 2306 | D11: 2 | E11: Tue | F11: 2299 | G11: =C11-F11 -> 7 | H11: =ABS(G11) -> 7 | I11: =G11^2 -> 49
B12: 45056 | C12: 1988 | D12: 2 | E12: Wed | F12: 1878 | G12: =C12-F12 -> 110 | H12: =ABS(G12) -> 110 | I12: =G12^2 -> 12100
B13: 45057 | C13: 1886 | D13: 2 | E13: Thu | F13: 1628 | G13: =C13-F13 -> 258 | H13: =ABS(G13) -> 258 | I13: =G13^2 -> 66564
B14: 45058 | C14: 1365 | D14: 2 | E14: Fri | F14: 1555 | G14: =C14-F14 -> -190 | H14: =ABS(G14) -> 190 | I14: =G14^2 -> 36100 | L14: Out of Sample
B15: 45059 | C15: 998 | D15: 2 | E15: Sat | F15: 1240 | G15: =C15-F15 -> -242 | H15: =ABS(G15) -> 242 | I15: =G15^2 -> 58564
B16: 45060 | C16: 1052 | D16: 2 | E16: Sun | F16: 864 | G16: =C16-F16 -> 188 | H16: =ABS(G16) -> 188 | I16: =G16^2 -> 35344 | L16: Mean Error | M16: =AVERAGE(G52:G58) -> 9.1428571
B17: 45061 | C17: 1905 | D17: 3 | E17: Mon | F17: 1882 | G17: =C17-F17 -> 23 | H17: =ABS(G17) -> 23 | I17: =G17^2 -> 529 | L17: Mean Absoulute Error | M17: =AVERAGE(H52:H58) -> 362.28571
B18: 45062 | C18: 1767 | D18: 3 | E18: Tue | F18: 2306 | G18: =C18-F18 -> -539 | H18: =ABS(G18) -> 539 | I18: =G18^2 -> 290521 | L18: Mean Squared Error | M18: =AVERAGE(I52:I58) -> 216194.29
B19: 45063 | C19: 1911 | D19: 3 | E19: Wed | F19: 1988 | G19: =C19-F19 -> -77 | H19: =ABS(G19) -> 77 | I19: =G19^2 -> 5929 | L19: RMSE | M19: =SQRT(M18) -> 464.96697
B20: 45064 | C20: 2036 | D20: 3 | E20: Thu | F20: 1886 | G20: =C20-F20 -> 150 | H20: =ABS(G20) -> 150 | I20: =G20^2 -> 22500
B21: 45065 | C21: 1428 | D21: 3 | E21: Fri | F21: 1365 | G21: =C21-F21 -> 63 | H21: =ABS(G21) -> 63 | I21: =G21^2 -> 3969
B22: 45066 | C22: 1008 | D22: 3 | E22: Sat | F22: 998 | G22: =C22-F22 -> 10 | H22: =ABS(G22) -> 10 | I22: =G22^2 -> 100
B23: 45067 | C23: 1082 | D23: 3 | E23: Sun | F23: 1052 | G23: =C23-F23 -> 30 | H23: =ABS(G23) -> 30 | I23: =G23^2 -> 900
B24: 45068 | C24: 1921 | D24: 4 | E24: Mon | F24: 1905 | G24: =C24-F24 -> 16 | H24: =ABS(G24) -> 16 | I24: =G24^2 -> 256
B25: 45069 | C25: 1780 | D25: 4 | E25: Tue | F25: 1767 | G25: =C25-F25 -> 13 | H25: =ABS(G25) -> 13 | I25: =G25^2 -> 169
B26: 45070 | C26: 2071 | D26: 4 | E26: Wed | F26: 1911 | G26: =C26-F26 -> 160 | H26: =ABS(G26) -> 160 | I26: =G26^2 -> 25600
B27: 45071 | C27: 1813 | D27: 4 | E27: Thu | F27: 2036 | G27: =C27-F27 -> -223 | H27: =ABS(G27) -> 223 | I27: =G27^2 -> 49729
B28: 45072 | C28: 1780 | D28: 4 | E28: Fri | F28: 1428 | G28: =C28-F28 -> 352 | H28: =ABS(G28) -> 352 | I28: =G28^2 -> 123904
B29: 45073 | C29: 1236 | D29: 4 | E29: Sat | F29: 1008 | G29: =C29-F29 -> 228 | H29: =ABS(G29) -> 228 | I29: =G29^2 -> 51984
B30: 45074 | C30: 1082 | D30: 4 | E30: Sun | F30: 1082 | G30: =C30-F30 -> 0 | H30: =ABS(G30) -> 0 | I30: =G30^2 -> 0
B31: 45075 | C31: 1777 | D31: 5 | E31: Mon | F31: 1921 | G31: =C31-F31 -> -144 | H31: =ABS(G31) -> 144 | I31: =G31^2 -> 20736
... B55: 45099 | C55: 2338 | D55: 8 | E55: Thu | F55: 3213 | G55: =C55-F55 -> -875 | H55: =ABS(G55) -> 875 | I55: =G55^2 -> 765625
B56: 45100 | C56: 2950 | E56: {='2.3 Identify Seasonality'!G56:G58} -> Fri | F56: 2194 | G56: =C56-F56 -> 756 | H56: =ABS(G56) -> 756 | I56: =G56^2 -> 571536
B57: 45101 | C57: 1601 | E57: Sat | F57: 1780 | G57: =C57-F57 -> -179 | H57: =ABS(G57) -> 179 | I57: =G57^2 -> 32041
B58: 45102 | C58: 1615 | E58: Sun | F58: 1408 | G58: =C58-F58 -> 207 | H58: =ABS(G58) -> 207 | I58: =G58^2 -> 42849

Sheet 3.2 Seasonal Average
B2: Date | C2: New Calls | D2: Week | E2: Day | F2: Seasonal Average Model | G2: Error | H2: Absolute Error | I2: Squared Error
B3: 45047 | C3: 1576
B4: 45048 | C4: 2299
B5: 45049 | C5: 1878
B6: 45050 | C6: 1628 | D6: {='2.3 Identify Seasonality'!F6:G55} -> 1 | E6: Thu
B7: 45051 | C7: 1555 | D7: 1 | E7: Fri
B8: 45052 | C8: 1240 | D8: 1 | E8: Sat
B9: 45053 | C9: 864 | D9: 1 | E9: Sun | L9: In-sample
B10: 45054 | C10: 1882 | D10: 2 | E10: Mon | F10: =C3 -> 1576 | G10: =C10-F10 -> 306 | H10: =ABS(G10) -> 306 | I10: =G10^2 -> 93636
B11: 45055 | C11: 2306 | D11: 2 | E11: Tue | F11: =C4 -> 2299 | G11: =C11-F11 -> 7 | H11: =ABS(G11) -> 7 | I11: =G11^2 -> 49 | L11: Mean Error | M11: =AVERAGE(G10:G51) -> 262.35595
B12: 45056 | C12: 1988 | D12: 2 | E12: Wed | F12: =C5 -> 1878 | G12: =C12-F12 -> 110 | H12: =ABS(G12) -> 110 | I12: =G12^2 -> 12100 | L12: Mean Absolute Error | M12: =AVERAGE(H10:H51) -> 364.29643
B13: 45057 | C13: 1886 | D13: 2 | E13: Thu | F13: =C6 -> 1628 | G13: =C13-F13 -> 258 | H13: =ABS(G13) -> 258 | I13: =G13^2 -> 66564 | L13: Mean Squared Error | M13: =AVERAGE(I10:I51) -> 254767.95
B14: 45058 | C14: 1365 | D14: 2 | E14: Fri | F14: =C7 -> 1555 | G14: =C14-F14 -> -190 | H14: =ABS(G14) -> 190 | I14: =G14^2 -> 36100 | L14: RMSE | M14: =SQRT(M13) -> 504.74543
B15: 45059 | C15: 998 | D15: 2 | E15: Sat | F15: =C8 -> 1240 | G15: =C15-F15 -> -242 | H15: =ABS(G15) -> 242 | I15: =G15^2 -> 58564
B16: 45060 | C16: 1052 | D16: 2 | E16: Sun | F16: =C9 -> 864 | G16: =C16-F16 -> 188 | H16: =ABS(G16) -> 188 | I16: =G16^2 -> 35344
B17: 45061 | C17: 1905 | D17: 3 | E17: Mon | F17: =AVERAGE(C3,C10) -> 1729 | G17: =C17-F17 -> 176 | H17: =ABS(G17) -> 176 | I17: =G17^2 -> 30976 | L17: Out of Sample
B18: 45062 | C18: 1767 | D18: 3 | E18: Tue | F18: =AVERAGE(C4,C11) -> 2302.5 | G18: =C18-F18 -> -535.5 | H18: =ABS(G18) -> 535.5 | I18: =G18^2 -> 286760.25
B19: 45063 | C19: 1911 | D19: 3 | E19: Wed | F19: =AVERAGE(C5,C12) -> 1933 | G19: =C19-F19 -> -22 | H19: =ABS(G19) -> 22 | I19: =G19^2 -> 484 | L19: Mean Error | M19: =AVERAGE(G52:G58) -> 597.44898
B20: 45064 | C20: 2036 | D20: 3 | E20: Thu | F20: =AVERAGE(C6,C13) -> 1757 | G20: =C20-F20 -> 279 | H20: =ABS(G20) -> 279 | I20: =G20^2 -> 77841 | L20: Mean Absolute Error | M20: =AVERAGE(H52:H58) -> 597.44898
B21: 45065 | C21: 1428 | D21: 3 | E21: Fri | F21: =AVERAGE(C7,C14) -> 1460 | G21: =C21-F21 -> -32 | H21: =ABS(G21) -> 32 | I21: =G21^2 -> 1024 | L21: Mean Squared Error | M21: =AVERAGE(I52:I58) -> 457454.28
B22: 45066 | C22: 1008 | D22: 3 | E22: Sat | F22: =AVERAGE(C8,C15) -> 1119 | G22: =C22-F22 -> -111 | H22: =ABS(G22) -> 111 | I22: =G22^2 -> 12321 | L22: RMSE | M22: =SQRT(M21) -> 676.35366
B23: 45067 | C23: 1082 | D23: 3 | E23: Sun | F23: =AVERAGE(C9,C16) -> 958 | G23: =C23-F23 -> 124 | H23: =ABS(G23) -> 124 | I23: =G23^2 -> 15376
B24: 45068 | C24: 1921 | D24: 4 | E24: Mon | F24: =AVERAGE(C3,C10,C17) -> 1787.6667 | G24: =C24-F24 -> 133.33333 | H24: =ABS(G24) -> 133.33333 | I24: =G24^2 -> 17777.778
B25: 45069 | C25: 1780 | D25: 4 | E25: Tue | F25: =AVERAGE(C4,C11,C18) -> 2124 | G25: =C25-F25 -> -344 | H25: =ABS(G25) -> 344 | I25: =G25^2 -> 118336
B26: 45070 | C26: 2071 | D26: 4 | E26: Wed | F26: =AVERAGE(C5,C12,C19) -> 1925.6667 | G26: =C26-F26 -> 145.33333 | H26: =ABS(G26) -> 145.33333 | I26: =G26^2 -> 21121.778
B27: 45071 | C27: 1813 | D27: 4 | E27: Thu | F27: =AVERAGE(C6,C13,C20) -> 1850 | G27: =C27-F27 -> -37 | H27: =ABS(G27) -> 37 | I27: =G27^2 -> 1369
B28: 45072 | C28: 1780 | D28: 4 | E28: Fri | F28: =AVERAGE(C7,C14,C21) -> 1449.3333 | G28: =C28-F28 -> 330.66667 | H28: =ABS(G28) -> 330.66667 | I28: =G28^2 -> 109340.44
B29: 45073 | C29: 1236 | D29: 4 | E29: Sat | F29: =AVERAGE(C8,C15,C22) -> 1082 | G29: =C29-F29 -> 154 | H29: =ABS(G29) -> 154 | I29: =G29^2 -> 23716
B30: 45074 | C30: 1082 | D30: 4 | E30: Sun | F30: =AVERAGE(C9,C16,C23) -> 999.33333 | G30: =C30-F30 -> 82.666667 | H30: =ABS(G30) -> 82.666667 | I30: =G30^2 -> 6833.7778
B31: 45075 | C31: 1777 | D31: 5 | E31: Mon | F31: =AVERAGE(C3,C10,C17,C24) -> 1821 | G31: =C31-F31 -> -44 | H31: =ABS(G31) -> 44 | I31: =G31^2 -> 1936
B32: 45076 | C32: 1766 | D32: 5 | E32: Tue | F32: =AVERAGE(C4,C11,C18,C25) -> 2038 | G32: =C32-F32 -> -272 | H32: =ABS(G32) -> 272 | I32: =G32^2 -> 73984
B33: 45077 | C33: 1884 | D33: 5 | E33: Wed | F33: =AVERAGE(C5,C12,C19,C26) -> 1962 | G33: =C33-F33 -> -78 | H33: =ABS(G33) -> 78 | I33: =G33^2 -> 6084
B34: 45078 | C34: 1780 | D34: 5 | E34: Thu | F34: =AVERAGE(C6,C13,C20,C27) -> 1840.75 | G34: =C34-F34 -> -60.75 | H34: =ABS(G34) -> 60.75 | I34: =G34^2 -> 3690.5625
B35: 45079 | C35: 1572 | D35: 5 | E35: Fri | F35: =AVERAGE(C7,C14,C21,C28) -> 1532 | G35: =C35-F35 -> 40 | H35: =ABS(G35) -> 40 | I35: =G35^2 -> 1600
B36: 45080 | C36: 948 | D36: 5 | E36: Sat | F36: =AVERAGE(C8,C15,C22,C29) -> 1120.5 | G36: =C36-F36 -> -172.5 | H36: =ABS(G36) -> 172.5 | I36: =G36^2 -> 29756.25
B37: 45081 | C37: 1085 | D37: 5 | E37: Sun | F37: =AVERAGE(C9,C16,C23,C30) -> 1020 | G37: =C37-F37 -> 65 | H37: =ABS(G37) -> 65 | I37: =G37^2 -> 4225
B38: 45082 | C38: 2917 | D38: 6 | E38: Mon | F38: =AVERAGE(C3,C10,C17,C24,C31) -> 1812.2 | G38: =C38-F38 -> 1104.8 | H38: =ABS(G38) -> 1104.8 | I38: =G38^2 -> 1220583
B39: 45083 | C39: 2801 | D39: 6 | E39: Tue | F39: =AVERAGE(C4,C11,C18,C25,C32) -> 1983.6 | G39: =C39-F39 -> 817.4 | H39: =ABS(G39) -> 817.4 | I39: =G39^2 -> 668142.76
B40: 45084 | C40: 3075 | D40: 6 | E40: Wed | F40: =AVERAGE(C5,C12,C19,C26,C33) -> 1946.4 | G40: =C40-F40 -> 1128.6 | H40: =ABS(G40) -> 1128.6 | I40: =G40^2 -> 1273738
B41: 45085 | C41: 2737 | D41: 6 | E41: Thu | F41: =AVERAGE(C6,C13,C20,C27,C34) -> 1828.6 | G41: =C41-F41 -> 908.4 | H41: =ABS(G41) -> 908.4 | I41: =G41^2 -> 825190.56
...

Sheet 3.3 Seasonal Exponential
B2: Date | C2: New Calls | D2: Week | E2: Day | F2: Level | G2: Season | H2: Seasonal Exponential Forecast | I2: Error | J2: Absolute Error | K2: Squared Error
B3: 45047 | C3: 1576 | F3: =AVERAGE($C$3:$C$9) -> 1577.1429 | G3: =C3/F3 -> 0.99927536
B4: 45048 | C4: 2299 | F4: =AVERAGE($C$3:$C$9) -> 1577.1429 | G4: =C4/F4 -> 1.4576993
B5: 45049 | C5: 1878 | F5: =AVERAGE($C$3:$C$9) -> 1577.1429 | G5: =C5/F5 -> 1.1907609
B6: 45050 | C6: 1628 | D6: {='2.3 Identify Seasonality'!F6:G55} -> 1 | E6: Thu | F6: =AVERAGE($C$3:$C$9) -> 1577.1429 | G6: =C6/F6 -> 1.0322464 | O6: Level (Alpha) | P6: 0.3
B7: 45051 | C7: 1555 | D7: 1 | E7: Fri | F7: =AVERAGE($C$3:$C$9) -> 1577.1429 | G7: =C7/F7 -> 0.98596014 | O7: Season (gamma) | P7: 0.35
B8: 45052 | C8: 1240 | D8: 1 | E8: Sat | F8: =AVERAGE($C$3:$C$9) -> 1577.1429 | G8: =C8/F8 -> 0.78623188
B9: 45053 | C9: 864 | D9: 1 | E9: Sun | F9: =AVERAGE($C$3:$C$9) -> 1577.1429 | G9: =C9/F9 -> 0.54782609
B10: 45054 | C10: 1882 | D10: 2 | E10: Mon | F10: =$P$6*(C10/G3)+(1-$P$6)*F9 -> 1669.0094 | G10: =$P$7*(C10/F10)+(1-$P$7)*G3 -> 1.0441942 | H10: =F10*G3 -> 1667.8 | I10: =C10-H10 -> 214.2 | J10: =ABS(I10) -> 214.2 | K10: =I10^2 -> 45881.64 | O10: In Sample
B11: 45055 | C11: 2306 | D11: 2 | E11: Tue | F11: =$P$6*(C11/G4)+(1-$P$6)*F10 -> 1642.8901 | G11: =$P$7*(C11/F11)+(1-$P$7)*G4 -> 1.4387729 | H11: =F11*G4 -> 2394.8397 | I11: =C11-H11 -> -88.839683 | J11: =ABS(I11) -> 88.839683 | K11: =I11^2 -> 7892.4892
B12: 45056 | C12: 1988 | D12: 2 | E12: Wed | F12: =$P$6*(C12/G5)+(1-$P$6)*F11 -> 1650.8793 | G12: =$P$7*(C12/F12)+(1-$P$7)*G5 -> 1.1954669 | H12: =F12*G5 -> 1965.8025 | I12: =C12-H12 -> 22.197544 | J12: =ABS(I12) -> 22.197544 | K12: =I12^2 -> 492.73095 | O12: Mean Error | P12: =AVERAGE(I10:I51) -> 34.705924
B13: 45057 | C13: 1886 | D13: 2 | E13: Thu | F13: =$P$6*(C13/G6)+(1-$P$6)*F12 -> 1703.7405 | G13: =$P$7*(C13/F13)+(1-$P$7)*G6 -> 1.0584018 | H13: =F13*G6 -> 1758.6799 | I13: =C13-H13 -> 127.32009 | J13: =ABS(I13) -> 127.32009 | K13: =I13^2 -> 16210.404 | O13: Mean Absoulte Error | P13: =AVERAGE(J10:J51) -> 174.82676
B14: 45058 | C14: 1365 | D14: 2 | E14: Fri | F14: =$P$6*(C14/G7)+(1-$P$6)*F13 -> 1607.9495 | G14: =$P$7*(C14/F14)+(1-$P$7)*G7 -> 0.93799163 | H14: =F14*G7 -> 1585.3741 | I14: =C14-H14 -> -220.37413 | J14: =ABS(I14) -> 220.37413 | K14: =I14^2 -> 48564.758 | O14: Mean Squared Error | P14: =AVERAGE(K10:K51) -> 56820.95
B15: 45059 | C15: 998 | D15: 2 | E15: Sat | F15: =$P$6*(C15/G8)+(1-$P$6)*F14 -> 1506.3683 | G15: =$P$7*(C15/F15)+(1-$P$7)*G8 -> 0.74293292 | H15: =F15*G8 -> 1184.3548 | I15: =C15-H15 -> -186.35482 | J15: =ABS(I15) -> 186.35482 | K15: =I15^2 -> 34728.119 | O15: RMSE | P15: =SQRT(P14) -> 238.37145
B16: 45060 | C16: 1052 | D16: 2 | E16: Sun | F16: =$P$6*(C16/G9)+(1-$P$6)*F15 -> 1630.5531 | G16: =$P$7*(C16/F16)+(1-$P$7)*G9 -> 0.58189991 | H16: =F16*G9 -> 893.25951 | I16: =C16-H16 -> 158.74049 | J16: =ABS(I16) -> 158.74049 | K16: =I16^2 -> 25198.542
B17: 45061 | C17: 1905 | D17: 3 | E17: Mon | F17: =$P$6*(C17/G10)+(1-$P$6)*F16 -> 1688.6991 | G17: =$P$7*(C17/F17)+(1-$P$7)*G10 -> 1.0735568 | H17: =F17*G10 -> 1763.3299 | I17: =C17-H17 -> 141.67013 | J17: =ABS(I17) -> 141.67013 | K17: =I17^2 -> 20070.425
B18: 45062 | C18: 1767 | D18: 3 | E18: Tue | F18: =$P$6*(C18/G11)+(1-$P$6)*F17 -> 1550.5283 | G18: =$P$7*(C18/F18)+(1-$P$7)*G11 -> 1.3340665 | H18: =F18*G11 -> 2230.8582 | I18: =C18-H18 -> -463.85823 | J18: =ABS(I18) -> 463.85823 | K18: =I18^2 -> 215164.45 | O18: Out of Sample
B19: 45063 | C19: 1911 | D19: 3 | E19: Wed | F19: =$P$6*(C19/G12)+(1-$P$6)*F18 -> 1564.9314 | G19: =$P$7*(C19/F19)+(1-$P$7)*G12 -> 1.2044524 | H19: =F19*G12 -> 1870.8238 | I19: =C19-H19 -> 40.176245 | J19: =ABS(I19) -> 40.176245 | K19: =I19^2 -> 1614.1307
B20: 45064 | C20: 2036 | D20: 3 | E20: Thu | F20: =$P$6*(C20/G13)+(1-$P$6)*F19 -> 1672.5485 | G20: =$P$7*(C20/F20)+(1-$P$7)*G13 -> 1.1140176 | H20: =F20*G13 -> 1770.2283 | I20: =C20-H20 -> 265.77166 | J20: =ABS(I20) -> 265.77166 | K20: =I20^2 -> 70634.574 | O20: Mean Error | P20: =AVERAGE(I52:I58) -> 21.276286
B21: 45065 | C21: 1428 | D21: 3 | E21: Fri | F21: =$P$6*(C21/G14)+(1-$P$6)*F20 -> 1627.5045 | G21: =$P$7*(C21/F21)+(1-$P$7)*G14 -> 0.91679049 | H21: =F21*G14 -> 1526.5856 | I21: =C21-H21 -> -98.585562 | J21: =ABS(I21) -> 98.585562 | K21: =I21^2 -> 9719.1131 | O21: Mean Absoulte Error | P21: =AVERAGE(J52:J58) -> 211.70192
B22: 45066 | C22: 1008 | D22: 3 | E22: Sat | F22: =$P$6*(C22/G15)+(1-$P$6)*F21 -> 1546.2885 | G22: =$P$7*(C22/F22)+(1-$P$7)*G15 -> 0.71106563 | H22: =F22*G15 -> 1148.7886 | I22: =C22-H22 -> -140.78865 | J22: =ABS(I22) -> 140.78865 | K22: =I22^2 -> 19821.443 | O22: Mean Squared Error | P22: =AVERAGE(K52:K58) -> 108501.69
B23: 45067 | C23: 1082 | D23: 3 | E23: Sun | F23: =$P$6*(C23/G16)+(1-$P$6)*F22 -> 1640.2299 | G23: =$P$7*(C23/F23)+(1-$P$7)*G16 -> 0.60911721 | H23: =F23*G16 -> 954.4496 | I23: =C23-H23 -> 127.5504 | J23: =ABS(I23) -> 127.5504 | K23: =I23^2 -> 16269.104 | O23: RMSE | P23: =SQRT(P22) -> 329.39595
B24: 45068 | C24: 1921 | D24: 4 | E24: Mon | F24: =$P$6*(C24/G17)+(1-$P$6)*F23 -> 1684.9746 | G24: =$P$7*(C24/F24)+(1-$P$7)*G17 -> 1.0968387 | H24: =F24*G17 -> 1808.9159 | I24: =C24-H24 -> 112.08407 | J24: =ABS(I24) -> 112.08407 | K24: =I24^2 -> 12562.838
B25: 45069 | C25: 1780 | D25: 4 | E25: Tue | F25: =$P$6*(C25/G18)+(1-$P$6)*F24 -> 1579.7621 | G25: =$P$7*(C25/F25)+(1-$P$7)*G18 -> 1.2615064 | H25: =F25*G18 -> 2107.5077 | I25: =C25-H25 -> -327.50767 | J25: =ABS(I25) -> 327.50767 | K25: =I25^2 -> 107261.27
B26: 45070 | C26: 2071 | D26: 4 | E26: Wed | F26: =$P$6*(C26/G19)+(1-$P$6)*F25 -> 1621.6696 | G26: =$P$7*(C26/F26)+(1-$P$7)*G19 -> 1.2298717 | H26: =F26*G19 -> 1953.2238 | I26: =C26-H26 -> 117.77616 | J26: =ABS(I26) -> 117.77616 | K26: =I26^2 -> 13871.224
B27: 45071 | C27: 1813 | D27: 4 | E27: Thu | F27: =$P$6*(C27/G20)+(1-$P$6)*F26 -> 1623.4016 | G27: =$P$7*(C27/F27)+(1-$P$7)*G20 -> 1.1149882 | H27: =F27*G20 -> 1808.4979 | I27: =C27-H27 -> 4.502143 | J27: =ABS(I27) -> 4.502143 | K27: =I27^2 -> 20.269292
B28: 45072 | C28: 1780 | D28: 4 | E28: Fri | F28: =$P$6*(C28/G21)+(1-$P$6)*F27 -> 1718.8479 | G28: =$P$7*(C28/F28)+(1-$P$7)*G21 -> 0.95836591 | H28: =F28*G21 -> 1575.8234 | I28: =C28-H28 -> 204.17661 | J28: =ABS(I28) -> 204.17661 | K28: =I28^2 -> 41688.088
B29: 45073 | C29: 1236 | D29: 4 | E29: Sat | F29: =$P$6*(C29/G22)+(1-$P$6)*F28 -> 1724.6644 | G29: =$P$7*(C29/F29)+(1-$P$7)*G22 -> 0.71302407 | H29: =F29*G22 -> 1226.3496 | I29: =C29-H29 -> 9.6504492 | J29: =ABS(I29) -> 9.6504492 | K29: =I29^2 -> 93.13117
B30: 45074 | C30: 1082 | D30: 4 | E30: Sun | F30: =$P$6*(C30/G23)+(1-$P$6)*F29 -> 1740.1674 | G30: =$P$7*(C30/F30)+(1-$P$7)*G23 -> 0.61354893 | H30: =F30*G23 -> 1059.9659 | I30: =C30-H30 -> 22.034075 | J30: =ABS(I30) -> 22.034075 | K30: =I30^2 -> 485.50048
B31: 45075 | C31: 1777 | D31: 5 | E31: Mon | F31: =$P$6*(C31/G24)+(1-$P$6)*F30 -> 1704.1504 | G31: =$P$7*(C31/F31)+(1-$P$7)*G24 -> 1.0779071 | H31: =F31*G24 -> 1869.1781 | I31: =C31-H31 -> -92.178073 | J31: =ABS(I31) -> 92.178073 | K31: =I31^2 -> 8496.7971
B32: 45076 | C32: 1766 | D32: 5 | E32: Tue | F32: =$P$6*(C32/G25)+(1-$P$6)*F31 -> 1612.8794 | G32: =$P$7*(C32/F32)+(1-$P$7)*G25 -> 1.2032068 | H32: =F32*G25 -> 2034.6576 | I32: =C32-H32 -> -268.65757 | J32: =ABS(I32) -> 268.65757 | K32: =I32^2 -> 72176.89
B33: 45077 | C33: 1884 | D33: 5 | E33: Wed | F33: =$P$6*(C33/G26)+(1-$P$6)*F32 -> 1588.5757 | G33: =$P$7*(C33/F33)+(1-$P$7)*G26 -> 1.2145054 | H33: =F33*G26 -> 1953.7443 | I33: =C33-H33 -> -69.744274 | J33: =ABS(I33) -> 69.744274 | K33: =I33^2 -> 4864.2637
B34: 45078 | C34: 1780 | D34: 5 | E34: Thu | F34: =$P$6*(C34/G27)+(1-$P$6)*F33 -> 1590.9318 | G34: =$P$7*(C34/F34)+(1-$P$7)*G27 -> 1.1163367 | H34: =F34*G27 -> 1773.8702 | I34: =C34-H34 -> 6.1297921 | J34: =ABS(I34) -> 6.1297921 | K34: =I34^2 -> 37.574352
B35: 45079 | C35: 1572 | D35: 5 | E35: Fri | F35: =$P$6*(C35/G28)+(1-$P$6)*F34 -> 1605.7399 | G35: =$P$7*(C35/F35)+(1-$P$7)*G28 -> 0.96558362 | H35: =F35*G28 -> 1538.8864 | I35: =C35-H35 -> 33.113632 | J35: =ABS(I35) -> 33.113632 | K35: =I35^2 -> 1096.5126
... B51: 45095 | C51: 1408 | D51: 7 | E51: Sun | F51: =$P$6*(C51/G44)+(1-$P$6)*F50 -> 2351.9652 | G51: =$P$7*(C51/F51)+(1-$P$7)*G44 -> 0.64443385 | H51: =F51*G44 -> 1573.6707 | I51: =C51-H51 -> -165.67071 | J51: =ABS(I51) -> 165.67071 | K51: =I51^2 -> 27446.785
B52: 45096 | C52: 2920 | D52: 8 | E52: Mon | F52: =$F$51 -> 2351.9652 | H52: =F52*G45 -> 2913.0827 | I52: =C52-H52 -> 6.917304 | J52: =ABS(I52) -> 6.917304 | K52: =I52^2 -> 47.849094
B53: 45097 | C53: 2647 | D53: 8 | E53: Tue | F53: =$F$51 -> 2351.9652 | H53: =F53*G46 -> 2786.3016 | I53: =C53-H53 -> -139.30156 | J53: =ABS(I53) -> 139.30156 | K53: =I53^2 -> 19404.925
B54: 45098 | C54: 3020 | D54: 8 | E54: Wed | F54: =$F$51 -> 2351.9652 | H54: =F54*G47 -> 3005.5372 | I54: =C54-H54 -> 14.462766 | J54: =ABS(I54) -> 14.462766 | K54: =I54^2 -> 209.17161
B55: 45099 | C55: 2338 | D55: 8 | E55: Thu | F55: =$F$51 -> 2351.9652 | H55: =F55*G48 -> 2834.3748 | I55: =C55-H55 -> -496.3748 | J55: =ABS(I55) -> 496.3748 | K55: =I55^2 -> 246387.94
B56: 45100 | C56: 2950 | D56: 8 | E56: {='2.3 Identify Seasonality'!G56:G58} -> Fri | F56: =$F$51 -> 2351.9652 | H56: =F56*G49 -> 2255.2704 | I56: =C56-H56 -> 694.72961 | J56: =ABS(I56) -> 694.72961 | K56: =I56^2 -> 482649.23
...

Sheet 4.1 Inventory Simulation
B5: Number of Installations | C5: Probability | D5: Cum. Probability | E5: Cut-off | F5: Number of Installations | I5: Ordering Cost | J5: 500
B6: 0 | C6: 0.05 | D6: =SUM($C$6:C6) -> 0.05 | E6: 0 | F6: 0 | I6: Holding Cost | J6: 10
B7: 1 | C7: 0.1 | D7: =SUM($C$6:C7) -> 0.15 | E7: =D6 -> 0.05 | F7: 1 | I7: Backorder Cost | J7: 20
B8: 2 | C8: 0.2 | D8: =SUM($C$6:C8) -> 0.35 | E8: =D7 -> 0.15 | F8: 2
B9: 3 | C9: 0.45 | D9: =SUM($C$6:C9) -> 0.8 | E9: =D8 -> 0.35 | F9: 3 | I9: Initial Stock | J9: 10
B10: 4 | C10: 0.2 | D10: =SUM($C$6:C10) -> 1 | E10: =D9 -> 0.8 | F10: 4 | I10: Reorder Point (R) | J10: 2
I11: Reorder Quantity (Q) | J11: 10
B13: Number of Boxes | C13: Probability | D13: Cum. Probability | E13: Cut-off | F13: Number of Boxes
B14: 2 | C14: 0.5 | D14: =SUM(C$14:C14) -> 0.5 | E14: 0 | F14: 2
B15: 3 | C15: 0.25 | D15: =SUM(C$14:C15) -> 0.75 | E15: =D14 -> 0.5 | F15: 3
B16: 4 | C16: 0.15 | D16: =SUM(C$14:C16) -> 0.9 | E16: =D15 -> 0.75 | F16: 4
B17: 5 | C17: 0.1 | D17: =SUM(C$14:C17) -> 1 | E17: =D16 -> 0.9 | F17: 5
I19: Inventory | L19: Ordering | O19: Costs
B20: Day | C20: Random Num 1 | D20: Installations | E20: Random 2 | F20: Boxes | G20: Total Boxes | I20: Beginning | J20: Ending | L20: Order | M20: Receive | O20: Ordering | P20: Holding | Q20: Backorder | R20: Total
B21: 1 | C21: ='4.2 Random Numbers'!B3 -> 0.10892056 | D21: =VLOOKUP(C21,E6:F10,2) -> 1 | G21: 0 | I21: =J9 -> 10 | J21: =I21-G21 -> 10 | L21: =IF(J21<=$J$10,$J$11,0) -> 0 | M21: 0 | O21: =IF(L21<>0,$J$5,0) -> 0 | P21: =IF(J21>=0,J21*$J$6,0) -> 100 | Q21: =IF(J21<0,-J21*$J$7,0) -> 0 | R21: =SUM(O21:Q21) -> 100
O22: =IF(L22<>0,$J$5,0) -> 0 | P22: =IF(J22>=0,J22*$J$6,0) -> 0 | Q22: =IF(J22<0,-J22*$J$7,0) -> 0 | R22: =SUM(O22:Q22) -> 0
B23: 2 | C23: ='4.2 Random Numbers'!B4 -> 0.41776788 | D23: =VLOOKUP(C23,E6:F10,2) -> 3 | E23: {='4.2 Random Numbers'!C3:C5} -> 0.73311563 | F23: =VLOOKUP(E23,$E$14:$F$17,2) -> 3 | G23: =SUM(F23:F25) -> 12 | I23: =J21+M23 -> 10 | J23: =I23-G23 -> -2 | L23: =IF(J23<=$J$10,$J$11,0) -> 10 | M23: =L21 -> 0 | O23: =IF(L23<>0,$J$5,0) -> 500 | P23: =IF(J23>=0,J23*$J$6,0) -> 0 | Q23: =IF(J23<0,-J23*$J$7,0) -> 40 | R23: =SUM(O23:Q23) -> 540
E24: 0.8051088 | F24: =VLOOKUP(E24,$E$14:$F$17,2) -> 4 | O24: =IF(L24<>0,$J$5,0) -> 0 | P24: =IF(J24>=0,J24*$J$6,0) -> 0 | Q24: =IF(J24<0,-J24*$J$7,0) -> 0 | R24: =SUM(O24:Q24) -> 0
E25: 0.95593127 | F25: =VLOOKUP(E25,$E$14:$F$17,2) -> 5 | O25: =IF(L25<>0,$J$5,0) -> 0 | P25: =IF(J25>=0,J25*$J$6,0) -> 0 | Q25: =IF(J25<0,-J25*$J$7,0) -> 0 | R25: =SUM(O25:Q25) -> 0
O26: =IF(L26<>0,$J$5,0) -> 0 | P26: =IF(J26>=0,J26*$J$6,0) -> 0 | Q26: =IF(J26<0,-J26*$J$7,0) -> 0 | R26: =SUM(O26:Q26) -> 0
B27: 3 | C27: ='4.2 Random Numbers'!B5 -> 0.4807886 | D27: =VLOOKUP(C27,E6:F10,2) -> 3 | E27: ='4.2 Random Numbers'!C6 -> 0.20343638 | F27: =VLOOKUP(E27,E14:F17,2) -> 2 | G27: =SUM(F27) -> 2 | I27: =J23+M27 -> 8 | J27: =I27-G27 -> 6 | L27: =IF(J27<=$J$10,$J$11,0) -> 0 | M27: =L23 -> 10 | O27: =IF(L27<>0,$J$5,0) -> 0 | P27: =IF(J27>=0,J27*$J$6,0) -> 60 | Q27: =IF(J27<0,-J27*$J$7,0) -> 0 | R27: =SUM(O27:Q27) -> 60
O28: =IF(L28<>0,$J$5,0) -> 0 | P28: =IF(J28>=0,J28*$J$6,0) -> 0 | Q28: =IF(J28<0,-J28*$J$7,0) -> 0 | R28: =SUM(O28:Q28) -> 0
O29: =IF(L29<>0,$J$5,0) -> 0 | P29: =IF(J29>=0,J29*$J$6,0) -> 0 | Q29: =IF(J29<0,-J29*$J$7,0) -> 0 | R29: =SUM(O29:Q29) -> 0
B30: 4 | C30: ='4.2 Random Numbers'!B6 -> 0.47840815 | D30: =VLOOKUP(C30,E6:F10,2) -> 3 | E30: {='4.2 Random Numbers'!C7:C8} -> 0.71004364 | F30: =VLOOKUP(E30,$E$14:$F$17,2) -> 3 | G30: =SUM(F30:F31) -> 5 | I30: =J27+M30 -> 6 | J30: =I30-G30 -> 1 | L30: =IF(J30<=$J$10,$J$11,0) -> 10 | M30: =L27 -> 0 | O30: =IF(L30<>0,$J$5,0) -> 500 | P30: =IF(J30>=0,J30*$J$6,0) -> 10 | Q30: =IF(J30<0,-J30*$J$7,0) -> 0 | R30: =SUM(O30:Q30) -> 510
E31: 0.20615253 | F31: =VLOOKUP(E31,$E$14:$F$17,2) -> 2 | O31: =IF(L31<>0,$J$5,0) -> 0 | P31: =IF(J31>=0,J31*$J$6,0) -> 0 | Q31: =IF(J31<0,-J31*$J$7,0) -> 0 | R31: =SUM(O31:Q31) -> 0
O32: =IF(L32<>0,$J$5,0) -> 0 | P32: =IF(J32>=0,J32*$J$6,0) -> 0 | Q32: =IF(J32<0,-J32*$J$7,0) -> 0 | R32: =SUM(O32:Q32) -> 0
B33: 5 | C33: ='4.2 Random Numbers'!B7 -> 0.24225593 | D33: =VLOOKUP(C33,E6:F10,2) -> 2 | E33: ='4.2 Random Numbers'!C9 -> 0.93389691 | F33: =VLOOKUP(E33,E14:F17,2) -> 5 | G33: =SUM(F33) -> 5 | I33: =J30+M33 -> 11 | J33: =I33-G33 -> 6 | L33: =IF(J33<=$J$10,$J$11,0) -> 0 | M33: =L30 -> 10 | O33: =IF(L33<>0,$J$5,0) -> 0 | P33: =IF(J33>=0,J33*$J$6,0) -> 60 | Q33: =IF(J33<0,-J33*$J$7,0) -> 0 | R33: =SUM(O33:Q33) -> 60
O34: =IF(L34<>0,$J$5,0) -> 0 | P34: =IF(J34>=0,J34*$J$6,0) -> 0 | Q34: =IF(J34<0,-J34*$J$7,0) -> 0 | R34: =SUM(O34:Q34) -> 0
B35: 6 | C35: ='4.2 Random Numbers'!B8 -> 0.37574389 | D35: =VLOOKUP(C35,E6:F10,2) -> 3 | E35: {='4.2 Random Numbers'!C10:C12} -> 0.33448286 | F35: =VLOOKUP(E35,$E$14:$F$17,2) -> 2 | G35: =SUM(F35:F37) -> 12 | I35: =J33+M35 -> 6 | J35: =I35-G35 -> -6 | L35: =IF(J35<=$J$10,$J$11,0) -> 10 | M35: =L33 -> 0 | O35: =IF(L35<>0,$J$5,0) -> 500 | P35: =IF(J35>=0,J35*$J$6,0) -> 0 | Q35: =IF(J35<0,-J35*$J$7,0) -> 120 | R35: =SUM(O35:Q35) -> 620
E36: 0.99514756 | F36: =VLOOKUP(E36,$E$14:$F$17,2) -> 5 | O36: =IF(L36<>0,$J$5,0) -> 0 | P36: =IF(J36>=0,J36*$J$6,0) -> 0 | Q36: =IF(J36<0,-J36*$J$7,0) -> 0 | R36: =SUM(O36:Q36) -> 0
E37: 0.98840297 | F37: =VLOOKUP(E37,$E$14:$F$17,2) -> 5 | O37: =IF(L37<>0,$J$5,0) -> 0 | P37: =IF(J37>=0,J37*$J$6,0) -> 0 | Q37: =IF(J37<0,-J37*$J$7,0) -> 0 | R37: =SUM(O37:Q37) -> 0
O38: =IF(L38<>0,$J$5,0) -> 0 | P38: =IF(J38>=0,J38*$J$6,0) -> 0 | Q38: =IF(J38<0,-J38*$J$7,0) -> 0 | R38: =SUM(O38:Q38) -> 0
B39: 7 | C39: ='4.2 Random Numbers'!B9 -> 0.62828455 | D39: =VLOOKUP(C39,E6:F10,2) -> 3 | G39: =SUM(F39) -> 0 | I39: =J35+M39 -> 4 | J39: =I39-G39 -> 4 | L39: =IF(J39<=$J$10,$J$11,0) -> 0 | M39: =L35 -> 10 | O39: =IF(L39<>0,$J$5,0) -> 0 | P39: =IF(J39>=0,J39*$J$6,0) -> 40 | Q39: =IF(J39<0,-J39*$J$7,0) -> 0 | R39: =SUM(O39:Q39) -> 40
Q41: Total Cost | R41: =SUM(R21:R39) -> 1930
Q43: Average Daily Cost | R43: =R41/7 -> 275.71429

Sheet 4.2 Random Numbers
B1: Random 1 | C1: Random 2
B2: 0.28678243 | C2: 0.32752464 | F2: Seed | G2: 2866
B3: 0.10892056 | C3: 0.73311563
B4: 0.41776788 | C4: 0.8051088
B5: 0.4807886 | C5: 0.95593127
B6: 0.47840815 | C6: 0.20343638
B7: 0.24225593 | C7: 0.71004364
B8: 0.37574389 | C8: 0.20615253
B9: 0.62828455 | C9: 0.93389691
B10: 0.8652913 | C10: 0.33448286
B11: 0.21234779 | C11: 0.99514756
B12: 0.078768273 | C12: 0.98840297
B13: 0.90838343 | C13: 0.31098361
B14: 0.78875088 | C14: 0.27872555
... B19: 0.2486343 | C19: 0.81066317

Sheet 5.1 Linear Programming
B5: Distance Matrix
B6: Engineer/Customer | C6: Job 1 | D6: Job 2 | E6: Job 3 | F6: Job 4 | G6: Job 5
B7: Tom | C7: 14 | D7: 7 | E7: 3 | F7: 7 | G7: 27
B8: Bob | C8: 20 | D8: 7 | E8: 12 | F8: 6 | G8: 30
B9: Paul | C9: 10 | D9: 3 | E9: 4 | F9: 5 | G9: 21
B10: Steve | C10: 8 | D10: 12 | E10: 7 | F10: 12 | G10: 21
B11: Lucas | C11: 13 | D11: 25 | E11: 24 | F11: 26 | G11: 8
B17: Decision Matrix
B18: Engineer/Customer | C18: Job 1 | D18: Job 2 | E18: Job 3 | F18: Job 4 | G18: Job 5
B19: Tom | C19: 0 | D19: 0 | E19: 1 | F19: 0 | G19: 0
B20: Bob | C20: 0 | D20: 0 | E20: 0 | F20: 0 | G20: 0
B21: Paul | C21: 0 | D21: 1 | E21: 0 | F21: 1 | G21: 0
B22: Steve | C22: 1 | D22: 0 | E22: 0 | F22: 0 | G22: 0
B23: Lucas | C23: 0 | D23: 0 | E23: 0 | F23: 0 | G23: 1
B25: Total | C25: =SUM(C19:C23) -> 1 | D25: =SUM(D19:D23) -> 1 | E25: =SUM(E19:E23) -> 1 | F25: =SUM(F19:F23) -> 1 | G25: =SUM(G19:G23) -> 1
B27: Total Distance Matrix
B28: Engineer/Customer | C28: Job 1 | D28: Job 2 | E28: Job 3 | F28: Job 4 | G28: Job 5
B29: Tom | C29: =C7*C19 -> 0 | D29: =D7*D19 -> 0 | E29: =E7*E19 -> 3 | F29: =F7*F19 -> 0 | G29: =G7*G19 -> 0
B30: Bob | C30: =C8*C20 -> 0 | D30: =D8*D20 -> 0 | E30: =E8*E20 -> 0 | F30: =F8*F20 -> 0 | G30: =G8*G20 -> 0
B31: Paul | C31: =C9*C21 -> 0 | D31: =D9*D21 -> 3 | E31: =E9*E21 -> 0 | F31: =F9*F21 -> 5 | G31: =G9*G21 -> 0
B32: Steve | C32: =C10*C22 -> 8 | D32: =D10*D22 -> 0 | E32: =E10*E22 -> 0 | F32: =F10*F22 -> 0 | G32: =G10*G22 -> 0
B33: Lucas | C33: =C11*C23 -> 0 | D33: =D11*D23 -> 0 | E33: =E11*E23 -> 0 | F33: =F11*F23 -> 0 | G33: =G11*G23 -> 8
G36: Total Distance | H36: =SUM(C29:G33) -> 27

Sheet 5.2 Answer Report 
A1: Microsoft Excel 16.0 Answer Report
A2: Worksheet: [NEHA FILE.xlsx]5.1 Linear Programming
A3: Report Created: 08/05/2025 2:36:42 am
A4: Result: Solver found a solution. All Constraints and optimality conditions are satisfied.
A5: Solver Engine
B6: Engine: Simplex LP
B7: Solution Time: 0.36 Seconds.
B8: Iterations: 12 Subproblems: 0
A9: Solver Options
B10: Max Time Unlimited, Iterations Unlimited, Precision 0.000001
B11: Max Subproblems Unlimited, Max Integer Sols Unlimited, Integer Tolerance 1%, Assume NonNegative
A14: Objective Cell (Min)
B15: Cell | C15: Name | D15: Original Value | E15: Final Value
B16: $H$36 | C16: Total Distance | D16: 27 | E16: 27
A19: Variable Cells
B20: Cell | C20: Name | D20: Original Value | E20: Final Value | F20: Integer
B21: $C$19:$G$23
B22: $C$19 | C22: Tom Job 1 | D22: 0 | E22: 0 | F22: Binary
B23: $D$19 | C23: Tom Job 2 | D23: 0 | E23: 0 | F23: Binary
B24: $E$19 | C24: Tom Job 3 | D24: 1 | E24: 1 | F24: Binary
B25: $F$19 | C25: Tom Job 4 | D25: 0 | E25: 0 | F25: Binary
B26: $G$19 | C26: Tom Job 5 | D26: 0 | E26: 0 | F26: Binary
B27: $C$20 | C27: Bob Job 1 | D27: 0 | E27: 0 | F27: Binary
B28: $D$20 | C28: Bob Job 2 | D28: 0 | E28: 0 | F28: Binary
B29: $E$20 | C29: Bob Job 3 | D29: 0 | E29: 0 | F29: Binary
B30: $F$20 | C30: Bob Job 4 | D30: 0 | E30: 0 | F30: Binary
B31: $G$20 | C31: Bob Job 5 | D31: 0 | E31: 0 | F31: Binary
B32: $C$21 | C32: Paul Job 1 | D32: 0 | E32: 0 | F32: Binary
B33: $D$21 | C33: Paul Job 2 | D33: 1 | E33: 1 | F33: Binary
... B46: $G$23 | C46: Lucas Job 5 | D46: 1 | E46: 1 | F46: Binary
A50: Constraints
B51: Cell | C51: Name | D51: Cell Value | E51: Formula | F51: Status | G51: Slack
B52: $C$25 | C52: Total Job 1 | D52: 1 | E52: $C$25=1 | F52: Binding | G52: 0
B53: $D$25 | C53: Total Job 2 | D53: 1 | E53: $D$25=1 | F53: Binding | G53: 0
B54: $E$25 | C54: Total Job 3 | D54: 1 | E54: $E$25=1 | F54: Binding | G54: 0
B55: $F$25 | C55: Total Job 4 | D55: 1 | E55: $F$25=1 | F55: Binding | G55: 0
B56: $G$25 | C56: Total Job 5 | D56: 1 | E56: $G$25=1 | F56: Binding | G56: 0
B57: $C$19:$G$23=Binary

Sheet 6.1 Poission Distribution
B2: Arrivals per Time Period (Lambda) | C2: 4 | D2: Arrivals per Hour
B3: Time Period per Arrival | C3: =60/C2 -> 15 | D3: Minutes per Arrival
B7: Poission Arrival Distribution
B8: Cumulative Probabilty | C8: Cut-off | D8: Minutes before arrival
B9: =_xlfn.POISSON.DIST(D9,$C$3,TRUE) -> 3.0590232e-07 | C9: 0 | D9: 0
B10: =_xlfn.POISSON.DIST(D10,$C$3,TRUE) -> 4.8944371e-06 | C10: =B9 -> 3.0590232e-07 | D10: 1
B11: =_xlfn.POISSON.DIST(D11,$C$3,TRUE) -> 3.9308448e-05 | C11: =B10 -> 4.8944371e-06 | D11: 2
B12: =_xlfn.POISSON.DIST(D12,$C$3,TRUE) -> 0.0002113785 | C12: =B11 -> 3.9308448e-05 | D12: 3
B13: =_xlfn.POISSON.DIST(D13,$C$3,TRUE) -> 0.00085664121 | C13: =B12 -> 0.0002113785 | D13: 4
B14: =_xlfn.POISSON.DIST(D14,$C$3,TRUE) -> 0.0027924293 | C14: =B13 -> 0.00085664121 | D14: 5
B15: =_xlfn.POISSON.DIST(D15,$C$3,TRUE) -> 0.0076318996 | C15: =B14 -> 0.0027924293 | D15: 6
B16: =_xlfn.POISSON.DIST(D16,$C$3,TRUE) -> 0.018002193 | C16: =B15 -> 0.0076318996 | D16: 7
B17: =_xlfn.POISSON.DIST(D17,$C$3,TRUE) -> 0.037446493 | C17: =B16 -> 0.018002193 | D17: 8
B18: =_xlfn.POISSON.DIST(D18,$C$3,TRUE) -> 0.069853661 | C18: =B17 -> 0.037446493 | D18: 9
B19: =_xlfn.POISSON.DIST(D19,$C$3,TRUE) -> 0.11846441 | C19: =B18 -> 0.069853661 | D19: 10
B20: =_xlfn.POISSON.DIST(D20,$C$3,TRUE) -> 0.1847518 | C20: =B19 -> 0.11846441 | D20: 11
B21: =_xlfn.POISSON.DIST(D21,$C$3,TRUE) -> 0.26761103 | C21: =B20 -> 0.1847518 | D21: 12
... B59: =_xlfn.POISSON.DIST(D59,$C$3,TRUE) -> 1 | C59: =B58 -> 1 | D59: 50

Sheet 6.2 Simulation Solution
B2: Arrivals per Hour | C2: 4 | D2: Poisson
B3: Inter-arrival rate | C3: =60/C2 -> 15 | D3: Exponential
B6: Service Rate | C6: =60/C7 -> 3 | D6: Exponential
B7: Mean Service Time | C7: 20
B11: Vehicle (Poisson) | F11: Mechanic 1 (Exponential) | I11: Mechanic 2 (Exponential) | L11: Waiting
B12: Vehicles | C12: Time between arrival | D12: Arrival Time | E12: Mechanic | F12: Start Time | G12: Service Time | H12: Completion Time | I12: Start Time | J12: Service Time | K12: Completion Time | L12: Idle 1 | M12: Idle 2 | N12: Wait Time
B13: 0 | C13: 0 | D13: 0 | E13: 0 | F13: 0 | G13: 0 | H13: 0 | I13: 0 | J13: 0 | K13: 0 | L13: 0 | M13: 0 | N13: 0
B14: 1 | C14: =VLOOKUP('6.3 Random Numbers'!B5,'6.1 Poission Distribution'!$C$9:$D$59,2) -> 13 | D14: =D13+C14 -> 13 | E14: =IF(MAX($H$13:H13)<MAX($K$13:K13),1,2) -> 2 | G14: =IF(F14="","",-$C$7*LN(1-'6.3 Random Numbers'!C5)) | H14: =IF(F14="","",F14+G14) | I14: =IF(E14=2,MAX(D14,$K$13:K13),"") -> 13 | J14: =IF(I14="","",-$C$7*LN(1-'6.3 Random Numbers'!D5)) -> 2.306434 | K14: =IF(I14="","",I14+J14) -> 15.306434 | L14: =IF(F14="","",F14-MAX($H$13:H13)) | M14: =IF(I14="","",I14-MAX($K$13:K13)) -> 13 | N14: =MAX(F14,I14)-D14 -> 0
B15: 2 | C15: =VLOOKUP('6.3 Random Numbers'!B6,'6.1 Poission Distribution'!$C$9:$D$59,2) -> 17 | D15: =D14+C15 -> 30 | E15: =IF(MAX($H$13:H14)<MAX($K$13:K14),1,2) -> 1 | F15: =IF(E15=1,MAX(D15,$H$13:H14),"") -> 30 | G15: =IF(F15="","",-$C$7*LN(1-'6.3 Random Numbers'!C6)) -> 10.817721 | H15: =IF(F15="","",F15+G15) -> 40.817721 | I15: =IF(E15=2,MAX(D15,$K$13:K14),"") | J15: =IF(I15="","",-$C$7*LN(1-'6.3 Random Numbers'!D6)) | K15: =IF(I15="","",I15+J15) | L15: =IF(F15="","",F15-MAX($H$13:H14)) -> 30 | M15: =IF(I15="","",I15-MAX($K$13:K14)) | N15: =MAX(F15,I15)-D15 -> 0
B16: 3 | C16: =VLOOKUP('6.3 Random Numbers'!B7,'6.1 Poission Distribution'!$C$9:$D$59,2) -> 15 | D16: =D15+C16 -> 45 | E16: =IF(MAX($H$13:H15)<MAX($K$13:K15),1,2) -> 2 | F16: =IF(E16=1,MAX(D16,$H$13:H15),"") | G16: =IF(F16="","",-$C$7*LN(1-'6.3 Random Numbers'!C7)) | H16: =IF(F16="","",F16+G16) | I16: =IF(E16=2,MAX(D16,$K$13:K15),"") -> 45 | J16: =IF(I16="","",-$C$7*LN(1-'6.3 Random Numbers'!D7)) -> 13.017398 | K16: =IF(I16="","",I16+J16) -> 58.017398 | L16: =IF(F16="","",F16-MAX($H$13:H15)) | M16: =IF(I16="","",I16-MAX($K$13:K15)) -> 29.693566 | N16: =MAX(F16,I16)-D16 -> 0
B17: 4 | C17: =VLOOKUP('6.3 Random Numbers'!B8,'6.1 Poission Distribution'!$C$9:$D$59,2) -> 12 | D17: =D16+C17 -> 57 | E17: =IF(MAX($H$13:H16)<MAX($K$13:K16),1,2) -> 1 | F17: =IF(E17=1,MAX(D17,$H$13:H16),"") -> 57 | G17: =IF(F17="","",-$C$7*LN(1-'6.3 Random Numbers'!C8)) -> 5.5481917 | H17: =IF(F17="","",F17+G17) -> 62.548192 | I17: =IF(E17=2,MAX(D17,$K$13:K16),"") | J17: =IF(I17="","",-$C$7*LN(1-'6.3 Random Numbers'!D8)) | K17: =IF(I17="","",I17+J17) | L17: =IF(F17="","",F17-MAX($H$13:H16)) -> 16.182279 | M17: =IF(I17="","",I17-MAX($K$13:K16)) | N17: =MAX(F17,I17)-D17 -> 0
B18: 5 | C18: =VLOOKUP('6.3 Random Numbers'!B9,'6.1 Poission Distribution'!$C$9:$D$59,2) -> 14 | D18: =D17+C18 -> 71 | E18: =IF(MAX($H$13:H17)<MAX($K$13:K17),1,2) -> 2 | F18: =IF(E18=1,MAX(D18,$H$13:H17),"") | G18: =IF(F18="","",-$C$7*LN(1-'6.3 Random Numbers'!C9)) | H18: =IF(F18="","",F18+G18) | I18: =IF(E18=2,MAX(D18,$K$13:K17),"") -> 71 | J18: =IF(I18="","",-$C$7*LN(1-'6.3 Random Numbers'!D9)) -> 19.792533 | K18: =IF(I18="","",I18+J18) -> 90.792533 | L18: =IF(F18="","",F18-MAX($H$13:H17)) | M18: =IF(I18="","",I18-MAX($K$13:K17)) -> 12.982602 | N18: =MAX(F18,I18)-D18 -> 0
B19: 6 | C19: =VLOOKUP('6.3 Random Numbers'!B10,'6.1 Poission Distribution'!$C$9:$D$59,2) -> 21 | D19: =D18+C19 -> 92 | E19: =IF(MAX($H$13:H18)<MAX($K$13:K18),1,2) -> 1 | F19: =IF(E19=1,MAX(D19,$H$13:H18),"") -> 92 | G19: =IF(F19="","",-$C$7*LN(1-'6.3 Random Numbers'!C10)) -> 40.092812 | H19: =IF(F19="","",F19+G19) -> 132.09281 | I19: =IF(E19=2,MAX(D19,$K$13:K18),"") | J19: =IF(I19="","",-$C$7*LN(1-'6.3 Random Numbers'!D10)) | K19: =IF(I19="","",I19+J19) | L19: =IF(F19="","",F19-MAX($H$13:H18)) -> 29.451808 | M19: =IF(I19="","",I19-MAX($K$13:K18)) | N19: =MAX(F19,I19)-D19 -> 0
B20: 7 | C20: =VLOOKUP('6.3 Random Numbers'!B11,'6.1 Poission Distribution'!$C$9:$D$59,2) -> 12 | D20: =D19+C20 -> 104 | E20: =IF(MAX($H$13:H19)<MAX($K$13:K19),1,2) -> 2 | F20: =IF(E20=1,MAX(D20,$H$13:H19),"") | G20: =IF(F20="","",-$C$7*LN(1-'6.3 Random Numbers'!C11)) | H20: =IF(F20="","",F20+G20) | I20: =IF(E20=2,MAX(D20,$K$13:K19),"") -> 104 | J20: =IF(I20="","",-$C$7*LN(1-'6.3 Random Numbers'!D11)) -> 1.6408734 | K20: =IF(I20="","",I20+J20) -> 105.64087 | L20: =IF(F20="","",F20-MAX($H$13:H19)) | M20: =IF(I20="","",I20-MAX($K$13:K19)) -> 13.207467 | N20: =MAX(F20,I20)-D20 -> 0
B21: 8 | C21: =VLOOKUP('6.3 Random Numbers'!B12,'6.1 Poission Distribution'!$C$9:$D$59,2) -> 24 | D21: =D20+C21 -> 128 | E21: =IF(MAX($H$13:H20)<MAX($K$13:K20),1,2) -> 2 | F21: =IF(E21=1,MAX(D21,$H$13:H20),"") | G21: =IF(F21="","",-$C$7*LN(1-'6.3 Random Numbers'!C12)) | H21: =IF(F21="","",F21+G21) | I21: =IF(E21=2,MAX(D21,$K$13:K20),"") -> 128 | J21: =IF(I21="","",-$C$7*LN(1-'6.3 Random Numbers'!D12)) -> 7.4498044 | K21: =IF(I21="","",I21+J21) -> 135.4498 | L21: =IF(F21="","",F21-MAX($H$13:H20)) | M21: =IF(I21="","",I21-MAX($K$13:K20)) -> 22.359127 | N21: =MAX(F21,I21)-D21 -> 0
B22: 9 | C22: =VLOOKUP('6.3 Random Numbers'!B13,'6.1 Poission Distribution'!$C$9:$D$59,2) -> 18 | D22: =D21+C22 -> 146 | E22: =IF(MAX($H$13:H21)<MAX($K$13:K21),1,2) -> 1 | F22: =IF(E22=1,MAX(D22,$H$13:H21),"") -> 146 | G22: =IF(F22="","",-$C$7*LN(1-'6.3 Random Numbers'!C13)) -> 6.5347112 | H22: =IF(F22="","",F22+G22) -> 152.53471 | I22: =IF(E22=2,MAX(D22,$K$13:K21),"") | J22: =IF(I22="","",-$C$7*LN(1-'6.3 Random Numbers'!D13)) | K22: =IF(I22="","",I22+J22) | L22: =IF(F22="","",F22-MAX($H$13:H21)) -> 13.907188 | M22: =IF(I22="","",I22-MAX($K$13:K21)) | N22: =MAX(F22,I22)-D22 -> 0
B23: 10 | C23: =VLOOKUP('6.3 Random Numbers'!B14,'6.1 Poission Distribution'!$C$9:$D$59,2) -> 10 | D23: =D22+C23 -> 156 | E23: =IF(MAX($H$13:H22)<MAX($K$13:K22),1,2) -> 2 | F23: =IF(E23=1,MAX(D23,$H$13:H22),"") | G23: =IF(F23="","",-$C$7*LN(1-'6.3 Random Numbers'!C14)) | H23: =IF(F23="","",F23+G23) | I23: =IF(E23=2,MAX(D23,$K$13:K22),"") -> 156 | J23: =IF(I23="","",-$C$7*LN(1-'6.3 Random Numbers'!D14)) -> 53.694667 | K23: =IF(I23="","",I23+J23) -> 209.69467 | L23: =IF(F23="","",F23-MAX($H$13:H22)) | M23: =IF(I23="","",I23-MAX($K$13:K22)) -> 20.550196 | N23: =MAX(F23,I23)-D23 -> 0
B24: 11 | C24: =VLOOKUP('6.3 Random Numbers'!B15,'6.1 Poission Distribution'!$C$9:$D$59,2) -> 15 | D24: =D23+C24 -> 171 | E24: =IF(MAX($H$13:H23)<MAX($K$13:K23),1,2) -> 1 | F24: =IF(E24=1,MAX(D24,$H$13:H23),"") -> 171 | G24: =IF(F24="","",-$C$7*LN(1-'6.3 Random Numbers'!C15)) -> 24.693249 | H24: =IF(F24="","",F24+G24) -> 195.69325 | I24: =IF(E24=2,MAX(D24,$K$13:K23),"") | J24: =IF(I24="","",-$C$7*LN(1-'6.3 Random Numbers'!D15)) | K24: =IF(I24="","",I24+J24) | L24: =IF(F24="","",F24-MAX($H$13:H23)) -> 18.465289 | M24: =IF(I24="","",I24-MAX($K$13:K23)) | N24: =MAX(F24,I24)-D24 -> 0
B25: 12 | C25: =VLOOKUP('6.3 Random Numbers'!B16,'6.1 Poission Distribution'!$C$9:$D$59,2) -> 9 | D25: =D24+C25 -> 180 | E25: =IF(MAX($H$13:H24)<MAX($K$13:K24),1,2) -> 1 | F25: =IF(E25=1,MAX(D25,$H$13:H24),"") -> 195.69325 | G25: =IF(F25="","",-$C$7*LN(1-'6.3 Random Numbers'!C16)) -> 5.7172558 | H25: =IF(F25="","",F25+G25) -> 201.4105 | I25: =IF(E25=2,MAX(D25,$K$13:K24),"") | J25: =IF(I25="","",-$C$7*LN(1-'6.3 Random Numbers'!D16)) | K25: =IF(I25="","",I25+J25) | L25: =IF(F25="","",F25-MAX($H$13:H24)) -> 0 | M25: =IF(I25="","",I25-MAX($K$13:K24)) | N25: =MAX(F25,I25)-D25 -> 15.693249
B26: 13 | C26: =VLOOKUP('6.3 Random Numbers'!B17,'6.1 Poission Distribution'!$C$9:$D$59,2) -> 15 | D26: =D25+C26 -> 195 | E26: =IF(MAX($H$13:H25)<MAX($K$13:K25),1,2) -> 1 | F26: =IF(E26=1,MAX(D26,$H$13:H25),"") -> 201.4105 | G26: =IF(F26="","",-$C$7*LN(1-'6.3 Random Numbers'!C17)) -> 91.720724 | H26: =IF(F26="","",F26+G26) -> 293.13123 | I26: =IF(E26=2,MAX(D26,$K$13:K25),"") | J26: =IF(I26="","",-$C$7*LN(1-'6.3 Random Numbers'!D17)) | K26: =IF(I26="","",I26+J26) | L26: =IF(F26="","",F26-MAX($H$13:H25)) -> 0 | M26: =IF(I26="","",I26-MAX($K$13:K25)) | N26: =MAX(F26,I26)-D26 -> 6.4105048
... B28: 15 | C28: =VLOOKUP('6.3 Random Numbers'!B19,'6.1 Poission Distribution'!$C$9:$D$59,2) -> 24 | D28: =D27+C28 -> 234 | E28: =IF(MAX($H$13:H27)<MAX($K$13:K27),1,2) -> 2 | F28: =IF(E28=1,MAX(D28,$H$13:H27),"") | G28: =IF(F28="","",-$C$7*LN(1-'6.3 Random Numbers'!C19)) | H28: =IF(F28="","",F28+G28) | I28: =IF(E28=2,MAX(D28,$K$13:K27),"") -> 234 | J28: =IF(I28="","",-$C$7*LN(1-'6.3 Random Numbers'!D19)) -> 3.3879687 | K28: =IF(I28="","",I28+J28) -> 237.38797 | L28: =IF(F28="","",F28-MAX($H$13:H27)) | M28: =IF(I28="","",I28-MAX($K$13:K27)) -> 19.527513 | N28: =MAX(F28,I28)-D28 -> 0
D32: Wait Time | G32: Mechanic 1
D33: Total Wait Time | E33: =SUM(N13:N28) -> 22.103754 | G33: Total Idle Time | H33: =SUM(L13:L28) -> 108.00656
D34: Average Wait Time | E34: =AVERAGE(N13:N28) -> 1.3814846 | G34: Idle Time % | H34: =$H$33/MAX(H13:H28) -> 0.36845806
D35: Maximum Wait Time | E35: =MAX(N13:N28) -> 15.693249
G37: Mechanic 2
G38: Total Idle Time | H38: =SUM(M13:M28) -> 131.6258
G39: Idle Time % | H39: =H38/MAX(K13:K28) -> 0.55447546

Sheet 6.3 Random Numbers
B2: Seed | C2: 2866
B4: Random 1 | C4: Random 2 | D4: Random 3
B5: 0.28678243 | C5: 0.32752464 | D5: 0.10892056
B6: 0.73311563 | C6: 0.41776788 | D6: 0.8051088
B7: 0.4807886 | C7: 0.95593127 | D7: 0.47840815
B8: 0.20343638 | C8: 0.24225593 | D8: 0.71004364
B9: 0.37574389 | C9: 0.20615253 | D9: 0.62828455
B10: 0.93389691 | C10: 0.8652913 | D10: 0.33448286
B11: 0.21234779 | C11: 0.99514756 | D11: 0.078768273
B12: 0.98840297 | C12: 0.90838343 | D12: 0.31098361
B13: 0.78875088 | C13: 0.27872555 | D13: 0.59898679
B14: 0.087405011 | C14: 0.31507309 | D14: 0.93176061
B15: 0.5474105 | C15: 0.70906705 | D15: 0.48088015
B16: 0.046937468 | C16: 0.2486343 | D16: 0.81066317
... B39: 0.54393139 | C39: 0.4603412 | D39: 0.11801508
